2024-09-06 14:52:09,584 INFO Starting ARC Prize 2024 Project...
2024-09-06 14:52:09,584 INFO Loading dataset...
2024-09-06 14:52:09,637 INFO Initializing the model...
2024-09-06 14:52:09,768 INFO Starting training...
2024-09-06 14:52:43,779 INFO Generating submission file...
2024-09-06 14:52:43,782 INFO Starting submission generation...
2024-09-06 14:52:43,782 INFO Opening sample submission file...
2024-09-06 14:52:43,786 INFO Opening test file: /Users/seungwonlee/ARC Prize 2024/ARCPrice2024/arc-prize-2024/arc-agi_test_challenges.json
2024-09-06 14:52:43,814 ERROR Error decoding JSON from the test file.
2024-09-06 14:52:43,814 ERROR Error in main process: Expecting value: line 1 column 1 (char 0)
Traceback (most recent call last):
  File "/Users/seungwonlee/ARC Prize 2024/ARCPrice2024/arc-prize-2024/main.py", line 51, in main
    submission = set_submission()
  File "/Users/seungwonlee/ARC Prize 2024/ARCPrice2024/arc-prize-2024/submission.py", line 39, in set_submission
    tasks_file = list(json.load(f).values())
  File "/Users/seungwonlee/opt/anaconda3/lib/python3.9/json/__init__.py", line 293, in load
    return loads(fp.read(),
  File "/Users/seungwonlee/opt/anaconda3/lib/python3.9/json/__init__.py", line 346, in loads
    return _default_decoder.decode(s)
  File "/Users/seungwonlee/opt/anaconda3/lib/python3.9/json/decoder.py", line 337, in decode
    obj, end = self.raw_decode(s, idx=_w(s, 0).end())
  File "/Users/seungwonlee/opt/anaconda3/lib/python3.9/json/decoder.py", line 355, in raw_decode
    raise JSONDecodeError("Expecting value", s, err.value) from None
json.decoder.JSONDecodeError: Expecting value: line 1 column 1 (char 0)
2024-09-08 23:04:49,764 INFO Starting ARC Prize 2024 Project...
2024-09-08 23:04:49,765 INFO Loading dataset...
2024-09-08 23:04:49,765 ERROR Error in main process: [Errno 2] No such file or directory: '/Users/seungwonlee/ARC Prize 2024/ARCPrice2024/arc-prize-2024/arc-agi_training_challenges.json'
Traceback (most recent call last):
  File "c:\Users\redca\Documents\GitHub\ARCPrice2024\arc-prize-2024\main.py", line 36, in main
    train_dataset = ARCDataset(train1_path)
                    ^^^^^^^^^^^^^^^^^^^^^^^
  File "c:\Users\redca\Documents\GitHub\ARCPrice2024\arc-prize-2024\dataset.py", line 11, in __init__
    with open(data_path, 'r') as f:
         ^^^^^^^^^^^^^^^^^^^^
FileNotFoundError: [Errno 2] No such file or directory: '/Users/seungwonlee/ARC Prize 2024/ARCPrice2024/arc-prize-2024/arc-agi_training_challenges.json'
2024-09-09 17:04:47,023 INFO Starting ARC Prize 2024 Project...
2024-09-09 17:04:47,023 INFO Loading dataset...
2024-09-09 17:04:47,076 INFO Initializing the model...
2024-09-09 17:04:47,210 INFO Starting training...
2024-09-09 17:05:20,221 INFO Generating submission file...
2024-09-09 17:05:20,223 INFO Starting submission generation...
2024-09-09 17:05:20,223 INFO Opening sample submission file...
2024-09-09 17:05:20,224 INFO Opening test file: /Users/seungwonlee/ARC Prize 2024/ARCPrice2024/arc-prize-2024/arc-agi_test_challenges.json
2024-09-09 17:05:20,252 ERROR Error decoding JSON from the test file.
2024-09-09 17:05:20,252 ERROR Error in main process: Expecting value: line 1 column 1 (char 0)
Traceback (most recent call last):
  File "/Users/seungwonlee/ARC Prize 2024/ARCPrice2024/arc-prize-2024/main.py", line 54, in main
    submission = set_submission()
  File "/Users/seungwonlee/ARC Prize 2024/ARCPrice2024/arc-prize-2024/submission.py", line 39, in set_submission
    tasks_file = list(json.load(f).values())
  File "/Users/seungwonlee/opt/anaconda3/lib/python3.9/json/__init__.py", line 293, in load
    return loads(fp.read(),
  File "/Users/seungwonlee/opt/anaconda3/lib/python3.9/json/__init__.py", line 346, in loads
    return _default_decoder.decode(s)
  File "/Users/seungwonlee/opt/anaconda3/lib/python3.9/json/decoder.py", line 337, in decode
    obj, end = self.raw_decode(s, idx=_w(s, 0).end())
  File "/Users/seungwonlee/opt/anaconda3/lib/python3.9/json/decoder.py", line 355, in raw_decode
    raise JSONDecodeError("Expecting value", s, err.value) from None
json.decoder.JSONDecodeError: Expecting value: line 1 column 1 (char 0)
2024-09-09 17:10:35,631 INFO Starting ARC Prize 2024 Project...
2024-09-09 17:10:35,632 INFO Loading dataset...
2024-09-09 17:10:35,684 INFO Initializing the model...
2024-09-09 17:10:35,807 INFO Starting training...
2024-09-09 17:11:07,215 INFO Generating submission file...
2024-09-09 17:11:07,216 INFO Starting submission generation...
2024-09-09 17:11:07,216 INFO Opening sample submission file...
2024-09-09 17:11:07,217 INFO Opening test file: /Users/seungwonlee/ARC Prize 2024/ARCPrice2024/arc-prize-2024/arc-agi_test_challenges.json
2024-09-09 17:11:07,268 INFO Processing submission data...
2024-09-09 17:11:07,268 ERROR Error in main process: name 'solvers' is not defined
Traceback (most recent call last):
  File "/Users/seungwonlee/ARC Prize 2024/ARCPrice2024/arc-prize-2024/main.py", line 54, in main
    submission = set_submission()
  File "/Users/seungwonlee/ARC Prize 2024/ARCPrice2024/arc-prize-2024/submission.py", line 67, in set_submission
    for sol in solvers:
NameError: name 'solvers' is not defined
